Workbook

Sheet Inputs
A1: COMPANY VALUATION MODEL v2.2 — INPUTS
A2: Every input is either taken directly from the financial statements or is an industry-, country- or market-wide parameter. No company-specific judgement values are used anywhere in this workbook.
A4: 1. COMPANY IDENTIFICATION
A6: Company name | B6: FICTIONAL DEMO SA
A7: Ticker | B7: DEMO.MI
A8: Reporting currency | B8: EUR
A9: Financial units | B9: Millions
A10: Latest fiscal year (FY0) | B10: 2025
A11: Valuation date | B11: 2026-08-19
A13: 2. MARKET DATA (as of the valuation date)
A14: Current share price | B14: 24.5 | G14: Primary listing, same currency as the statements.
A15: Diluted shares outstanding (millions) | B15: 420 | G15: Point-in-time from the latest balance sheet, not weighted average.
A16: Market capitalisation (millions) | B16: =B14*B15 -> 10290 | G16: Calculated.
A18: 3. INCOME STATEMENT — five fiscal years (millions)
B19: FY-4 | C19: FY-3 | D19: FY-2 | E19: FY-1 | F19: FY0
A20: Revenue | B20: 3800 | C20: 3950 | D20: 4180 | E20: 4310 | F20: 4520
A21: EBIT | B21: 420 | C21: 455 | D21: 500 | E21: 505 | F21: 545
A22: Depreciation & amortisation | B22: 290 | C22: 300 | D22: 315 | E22: 322 | F22: 335
A23: Interest expense (gross) | B23: 62 | C23: 60 | D23: 58 | E23: 61 | F23: 59
A24: Pre-tax income | B24: 358 | C24: 398 | D24: 445 | E24: 447 | F24: 490
A25: Income tax expense | B25: 97 | C25: 107 | D25: 120 | E25: 121 | F25: 132
A26: Net income attributable to common shareholders | B26: 255 | C26: 285 | D26: 320 | E26: 320 | F26: 352
A28: 4. BALANCE SHEET (millions)
B29: FY-4 | C29: FY-3 | D29: FY-2 | E29: FY-1 | F29: FY0
A30: Cash & cash equivalents | B30: 210 | C30: 235 | D30: 260 | E30: 275 | F30: 300
A31: Short-term investments / marketable securities | B31: 40 | C31: 45 | D31: 50 | E31: 55 | F31: 60
A32: Total current assets | B32: 1450 | C32: 1520 | D32: 1610 | E32: 1665 | F32: 1750
A33: Total current liabilities | B33: 1180 | C33: 1225 | D33: 1290 | E33: 1330 | F33: 1390
A34: Short-term debt + current portion of LTD (incl. current leases) | B34: 150 | C34: 145 | D34: 160 | E34: 155 | F34: 165
A35: Long-term debt incl. capitalised lease liabilities | B35: 1250 | C35: 1220 | D35: 1240 | E35: 1210 | F35: 1180
A36: Preferred stock | B36: 0 | C36: 0 | D36: 0 | E36: 0 | F36: 0
A37: Minority / non-controlling interest | B37: 45 | C37: 48 | D37: 52 | E37: 55 | F37: 58
A38: Total equity (incl. minority interest and preferred) | B38: 1620 | C38: 1720 | D38: 1850 | E38: 1960 | F38: 2100
A39: Equity-method investments / investments in associates | B39: 85 | C39: 88 | D39: 92 | E39: 95 | F39: 100
A40: Total assets | B40: 4400 | C40: 4560 | D40: 4790 | E40: 4930 | F40: 5150 | G40: Used by the holding-company diagnostic only; not part of the valuation chain.
A42: 5. CASH-FLOW STATEMENT (millions)
B43: FY-4 | C43: FY-3 | D43: FY-2 | E43: FY-1 | F43: FY0
A44: Capital expenditure (positive) | B44: 355 | C44: 370 | D44: 395 | E44: 405 | F44: 420
A45: Acquisitions, net of divestitures | B45: 0 | C45: 40 | D45: 0 | E45: 25 | F45: 0
A47: 6. MARKET-WIDE PARAMETERS — update quarterly, identical for every company
...

Sheet RefData
A1: SYNTHETIC CREDIT RATING — INTEREST COVERAGE TO DEFAULT SPREAD
A2: Interest coverage = normalised EBIT / median gross interest expense. The model looks up the highest threshold the company clears and adds that spread to the risk-free rate.
A3: Coverage ratio >= | B3: Implied rating | C3: Default spread
A4: -100000 | B4: D | C4: 0.19 | D4: Source: Damodaran, 'Ratings, Interest Coverage Ratios and Default Spreads' (large non-financial firms). Refresh annually. These are the only hardcoded market data in the workbook.
A5: 0.2 | B5: C | C5: 0.16
A6: 0.65 | B6: CC | C6: 0.1261
A7: 0.8 | B7: CCC | C7: 0.0885
A8: 1.25 | B8: B- | C8: 0.0509
A9: 1.5 | B9: B | C9: 0.0321
A10: 1.75 | B10: B+ | C10: 0.0275
A11: 2 | B11: BB | C11: 0.0184
A12: 2.25 | B12: BB+ | C12: 0.0138
A13: 2.5 | B13: BBB | C13: 0.0111
A14: 3 | B14: A- | C14: 0.0089
A15: 4.25 | B15: A | C15: 0.0078
A16: 5.5 | B16: A+ | C16: 0.007
... A18: 8.5 | B18: AAA | C18: 0.004
A20: Thresholds must remain sorted ascending — MATCH(...,1) depends on it.
A22: Active table (LARGE or SMALL) | B22: LARGE
A23: Table vintage (YYYY-MM of publication) | B23: 2026-01
A24: Size cut-off — market cap, EUR millions | B24: 4300
A26: A4:C18 holds whichever table applies to this company. The pipeline writes all 45 cells from refdata_tables.json before recalculating, then D120 verifies the choice against market capitalisation. Cut-off is Damodaran's USD 5bn converted at 1.16 and FIXED in EUR: review it each February with the tables, never float it with the exchange rate.

Sheet Valuation
B1: VALUATION ENGINE v2.2
B3: A. NORMALISED OPERATING PERFORMANCE (five-year median)
D4: FY-4 | E4: FY-3 | F4: FY-2 | G4: FY-1 | H4: FY0
B5: Revenue, FY0 | D5: =Inputs!F20 -> 4520
B6: EBIT margin by year | D6: =IFERROR(Inputs!B21/Inputs!B20,0) -> 0.11052632 | E6: =IFERROR(Inputs!C21/Inputs!C20,0) -> 0.11518987 | F6: =IFERROR(Inputs!D21/Inputs!D20,0) -> 0.11961722 | G6: =IFERROR(Inputs!E21/Inputs!E20,0) -> 0.11716937 | H6: =IFERROR(Inputs!F21/Inputs!F20,0) -> 0.12057522
B7: Normalised EBIT margin (median of 5) | D7: =MEDIAN(D6:H6) -> 0.11716937 | N7: Median, not mean: one distorted year cannot move it.
B8: Normalised EBIT | D8: =D5*D7 -> 529.60557
B9: Effective tax rate by year | D9: =IFERROR(Inputs!B25/Inputs!B24,0) -> 0.27094972 | E9: =IFERROR(Inputs!C25/Inputs!C24,0) -> 0.26884422 | F9: =IFERROR(Inputs!D25/Inputs!D24,0) -> 0.26966292 | G9: =IFERROR(Inputs!E25/Inputs!E24,0) -> 0.27069351 | H9: =IFERROR(Inputs!F25/Inputs!F24,0) -> 0.26938776
B10: Median effective tax rate | D10: =MEDIAN(D9:H9) -> 0.26966292
B11: Normalised tax rate (stage-1 starting point) | D11: =IF(OR(D10<0.05,D10>0.45),Inputs!B54,D10) -> 0.26966292 | N11: Falls back to the statutory rate only when the median is implausible.
B12: Normalised NOPAT | D12: =D8*(1-D11) -> 386.79058
B14: B. INVESTED CAPITAL AND RETURNS
D15: FY-4 | E15: FY-3 | F15: FY-2 | G15: FY-1 | H15: FY0
B16: Invested capital | D16: =Inputs!B34+Inputs!B35+Inputs!B38-Inputs!B30-Inputs!B31-Inputs!B39 -> 2685 | E16: =Inputs!C34+Inputs!C35+Inputs!C38-Inputs!C30-Inputs!C31-Inputs!C39 -> 2717 | F16: =Inputs!D34+Inputs!D35+Inputs!D38-Inputs!D30-Inputs!D31-Inputs!D39 -> 2848 | G16: =Inputs!E34+Inputs!E35+Inputs!E38-Inputs!E30-Inputs!E31-Inputs!E39 -> 2900 | H16: =Inputs!F34+Inputs!F35+Inputs!F38-Inputs!F30-Inputs!F31-Inputs!F39 -> 2985
B17: Working capital (ex cash, ex short-term debt) | D17: =(Inputs!B32-Inputs!B30-Inputs!B31)-(Inputs!B33-Inputs!B34) -> 170 | E17: =(Inputs!C32-Inputs!C30-Inputs!C31)-(Inputs!C33-Inputs!C34) -> 160 | F17: =(Inputs!D32-Inputs!D30-Inputs!D31)-(Inputs!D33-Inputs!D34) -> 170 | G17: =(Inputs!E32-Inputs!E30-Inputs!E31)-(Inputs!E33-Inputs!E34) -> 160 | H17: =(Inputs!F32-Inputs!F30-Inputs!F31)-(Inputs!F33-Inputs!F34) -> 165
B18: Average invested capital (FY-1, FY0) | D18: =AVERAGE(G16:H16) -> 2942.5
B19: Raw normalised ROIC | D19: =IF(D18<=0,Inputs!B66,D12/D18) -> 0.13144965
B20: Bounded normalised ROIC | D20: =MIN(Inputs!B66,MAX(Inputs!B67,D19)) -> 0.13144965
B22: C. REINVESTMENT (two independent estimates, conservative one selected)
B23: Cumulative net reinvestment, FY-3 to FY0 | D23: =SUM(Inputs!C44:F44)+SUM(Inputs!C45:F45)-SUM(Inputs!C22:F22)+(H17-D17) -> 378 | N23: Capex + acquisitions - D&A + change in working capital, over four years.
B24: Cumulative NOPAT, FY-3 to FY0 | D24: =SUM(Inputs!C21:F21)*(1-D11) -> 1464.3258
B25: Reinvestment rate — cash-flow based | D25: =IF(D24<=0,0,D23/D24) -> 0.25813927
B26: Revenue CAGR, FY-4 to FY0 | D26: =IFERROR(IF(Inputs!B20<=0,0,(Inputs!F20/Inputs!B20)^(1/4)-1),0) -> 0.044332298
B27: Implied reinvestment — sales-to-capital based | D27: =IFERROR(D5*MAX(0,D26)/Inputs!B58,0) -> 125.23874 | N27: Revenue growth divided by the industry sales-to-capital ratio.
B28: Reinvestment rate — sales-to-capital based | D28: =IF(D12<=0,0,D27/D12) -> 0.32378953
B29: Selected reinvestment rate (lower of the two) | D29: =MIN(Inputs!B68,MAX(0,MIN(D25,D28))) -> 0.25813927 | N29: The lower estimate produces the lower growth rate. Conservative by rule, not by judgement.
B30: Divergence between the two estimates | D30: =IFERROR(ABS(D25-D28)/MAX(ABS(D25),ABS(D28)),0) -> 0.20275598
B32: D. COST OF CAPITAL
B33: Total debt, FY0 | D33: =Inputs!F34+Inputs!F35 -> 1345
B34: Debt / equity (market) | D34: =IFERROR(D33/Inputs!B16,0) -> 0.13070943
B35: Relevered equity beta | D35: =Inputs!B57*(1+(1-Inputs!B54)*D34) -> 0.93443829 | N35: Bottom-up: industry asset beta relevered at this company's own capital structure. No regression.
B36: Cost of equity | D36: =Inputs!B48+D35*Inputs!B49+Inputs!B53 -> 0.085853038
B37: Median gross interest expense | D37: =MEDIAN(Inputs!B23:F23) -> 60
B38: Interest coverage ratio | D38: =IF(D37<=0,100,D8/D37) -> 8.8267595
B39: Implied credit rating | D39: =INDEX(RefData!B4:B18,MATCH(D38,RefData!A4:A18,1)) -> AAA
B40: Synthetic default spread | D40: =INDEX(RefData!C4:C18,MATCH(D38,RefData!A4:A18,1)) -> 0.004
B41: Synthetic pre-tax cost of debt | D41: =Inputs!B48+D40+Inputs!B53 -> 0.045
B42: Actual effective interest rate | D42: =IFERROR(IF(AVERAGE(Inputs!E34:E35,Inputs!F34:F35)<=0,0,Inputs!F23/((Inputs!E34+Inputs!E35+Inputs!F34+Inputs!F35)/2)),0) -> 0.043542435 | N42: Gross interest expense over average gross debt. Straight from the statements.
B43: Pre-tax cost of debt (higher of the two, capped) | D43: =MIN(0.25,MAX(D41,D42)) -> 0.045 | N43: Taking the higher is conservative and mechanical; the cap stops a data error from dominating.
B44: After-tax cost of debt | D44: =D43*(1-Inputs!B54) -> 0.0342
...

Sheet Sensitivity
B1: SENSITIVITY — VALUE PER SHARE
B2: The operating forecast is held fixed; only the discount rate and the terminal growth rate move. This isolates the effect of the cost of capital, which is the least observable input in the model.
B4: Terminal growth -> | C4: =Valuation!$D$51+-0.005 -> 0.021 | D4: =Valuation!$D$51+0 -> 0.026 | E4: =Valuation!$D$51+0.005 -> 0.031
B5: =Valuation!$D$47+-0.01 -> 0.069881973 | C5: =IFERROR((SUMPRODUCT(Valuation!$D$65:$M$65/(1+$B5)^(Valuation!$D$58:$M$58-Valuation!$D$54))+(Valuation!$M$63*(1+C$4)*(1-C$4/MAX($B5,C$4+Inputs!$B$70))/MAX($B5-C$4,Inputs!$B$70))/(1+$B5)^(Valuation!$D$55-Valuation!$D$54)+(Valuation!$D$82-Valuation!$D$76))/Inputs!$B$15,0) -> 13.663454 | D5: =IFERROR((SUMPRODUCT(Valuation!$D$65:$M$65/(1+$B5)^(Valuation!$D$58:$M$58-Valuation!$D$54))+(Valuation!$M$63*(1+D$4)*(1-D$4/MAX($B5,D$4+Inputs!$B$70))/MAX($B5-D$4,Inputs!$B$70))/(1+$B5)^(Valuation!$D$55-Valuation!$D$54)+(Valuation!$D$82-Valuation!$D$76))/Inputs!$B$15,0) -> 13.712695 | E5: =IFERROR((SUMPRODUCT(Valuation!$D$65:$M$65/(1+$B5)^(Valuation!$D$58:$M$58-Valuation!$D$54))+(Valuation!$M$63*(1+E$4)*(1-E$4/MAX($B5,E$4+Inputs!$B$70))/MAX($B5-E$4,Inputs!$B$70))/(1+$B5)^(Valuation!$D$55-Valuation!$D$54)+(Valuation!$D$82-Valuation!$D$76))/Inputs!$B$15,0) -> 13.761936
B6: =Valuation!$D$47+-0.005 -> 0.074881973 | C6: =IFERROR((SUMPRODUCT(Valuation!$D$65:$M$65/(1+$B6)^(Valuation!$D$58:$M$58-Valuation!$D$54))+(Valuation!$M$63*(1+C$4)*(1-C$4/MAX($B6,C$4+Inputs!$B$70))/MAX($B6-C$4,Inputs!$B$70))/(1+$B6)^(Valuation!$D$55-Valuation!$D$54)+(Valuation!$D$82-Valuation!$D$76))/Inputs!$B$15,0) -> 12.460261 | D6: =IFERROR((SUMPRODUCT(Valuation!$D$65:$M$65/(1+$B6)^(Valuation!$D$58:$M$58-Valuation!$D$54))+(Valuation!$M$63*(1+D$4)*(1-D$4/MAX($B6,D$4+Inputs!$B$70))/MAX($B6-D$4,Inputs!$B$70))/(1+$B6)^(Valuation!$D$55-Valuation!$D$54)+(Valuation!$D$82-Valuation!$D$76))/Inputs!$B$15,0) -> 12.504223 | E6: =IFERROR((SUMPRODUCT(Valuation!$D$65:$M$65/(1+$B6)^(Valuation!$D$58:$M$58-Valuation!$D$54))+(Valuation!$M$63*(1+E$4)*(1-E$4/MAX($B6,E$4+Inputs!$B$70))/MAX($B6-E$4,Inputs!$B$70))/(1+$B6)^(Valuation!$D$55-Valuation!$D$54)+(Valuation!$D$82-Valuation!$D$76))/Inputs!$B$15,0) -> 12.548185
B7: =Valuation!$D$47+0 -> 0.079881973 | C7: =IFERROR((SUMPRODUCT(Valuation!$D$65:$M$65/(1+$B7)^(Valuation!$D$58:$M$58-Valuation!$D$54))+(Valuation!$M$63*(1+C$4)*(1-C$4/MAX($B7,C$4+Inputs!$B$70))/MAX($B7-C$4,Inputs!$B$70))/(1+$B7)^(Valuation!$D$55-Valuation!$D$54)+(Valuation!$D$82-Valuation!$D$76))/Inputs!$B$15,0) -> 11.414394 | D7: =IFERROR((SUMPRODUCT(Valuation!$D$65:$M$65/(1+$B7)^(Valuation!$D$58:$M$58-Valuation!$D$54))+(Valuation!$M$63*(1+D$4)*(1-D$4/MAX($B7,D$4+Inputs!$B$70))/MAX($B7-D$4,Inputs!$B$70))/(1+$B7)^(Valuation!$D$55-Valuation!$D$54)+(Valuation!$D$82-Valuation!$D$76))/Inputs!$B$15,0) -> 11.453827 | E7: =IFERROR((SUMPRODUCT(Valuation!$D$65:$M$65/(1+$B7)^(Valuation!$D$58:$M$58-Valuation!$D$54))+(Valuation!$M$63*(1+E$4)*(1-E$4/MAX($B7,E$4+Inputs!$B$70))/MAX($B7-E$4,Inputs!$B$70))/(1+$B7)^(Valuation!$D$55-Valuation!$D$54)+(Valuation!$D$82-Valuation!$D$76))/Inputs!$B$15,0) -> 11.49326
B8: =Valuation!$D$47+0.005 -> 0.084881973 | C8: =IFERROR((SUMPRODUCT(Valuation!$D$65:$M$65/(1+$B8)^(Valuation!$D$58:$M$58-Valuation!$D$54))+(Valuation!$M$63*(1+C$4)*(1-C$4/MAX($B8,C$4+Inputs!$B$70))/MAX($B8-C$4,Inputs!$B$70))/(1+$B8)^(Valuation!$D$55-Valuation!$D$54)+(Valuation!$D$82-Valuation!$D$76))/Inputs!$B$15,0) -> 10.497733 | D8: =IFERROR((SUMPRODUCT(Valuation!$D$65:$M$65/(1+$B8)^(Valuation!$D$58:$M$58-Valuation!$D$54))+(Valuation!$M$63*(1+D$4)*(1-D$4/MAX($B8,D$4+Inputs!$B$70))/MAX($B8-D$4,Inputs!$B$70))/(1+$B8)^(Valuation!$D$55-Valuation!$D$54)+(Valuation!$D$82-Valuation!$D$76))/Inputs!$B$15,0) -> 10.53325 | E8: =IFERROR((SUMPRODUCT(Valuation!$D$65:$M$65/(1+$B8)^(Valuation!$D$58:$M$58-Valuation!$D$54))+(Valuation!$M$63*(1+E$4)*(1-E$4/MAX($B8,E$4+Inputs!$B$70))/MAX($B8-E$4,Inputs!$B$70))/(1+$B8)^(Valuation!$D$55-Valuation!$D$54)+(Valuation!$D$82-Valuation!$D$76))/Inputs!$B$15,0) -> 10.568766
B9: =Valuation!$D$47+0.01 -> 0.089881973 | C9: =IFERROR((SUMPRODUCT(Valuation!$D$65:$M$65/(1+$B9)^(Valuation!$D$58:$M$58-Valuation!$D$54))+(Valuation!$M$63*(1+C$4)*(1-C$4/MAX($B9,C$4+Inputs!$B$70))/MAX($B9-C$4,Inputs!$B$70))/(1+$B9)^(Valuation!$D$55-Valuation!$D$54)+(Valuation!$D$82-Valuation!$D$76))/Inputs!$B$15,0) -> 9.6884294 | D9: =IFERROR((SUMPRODUCT(Valuation!$D$65:$M$65/(1+$B9)^(Valuation!$D$58:$M$58-Valuation!$D$54))+(Valuation!$M$63*(1+D$4)*(1-D$4/MAX($B9,D$4+Inputs!$B$70))/MAX($B9-D$4,Inputs!$B$70))/(1+$B9)^(Valuation!$D$55-Valuation!$D$54)+(Valuation!$D$82-Valuation!$D$76))/Inputs!$B$15,0) -> 9.7205369 | E9: =IFERROR((SUMPRODUCT(Valuation!$D$65:$M$65/(1+$B9)^(Valuation!$D$58:$M$58-Valuation!$D$54))+(Valuation!$M$63*(1+E$4)*(1-E$4/MAX($B9,E$4+Inputs!$B$70))/MAX($B9-E$4,Inputs!$B$70))/(1+$B9)^(Valuation!$D$55-Valuation!$D$54)+(Valuation!$D$82-Valuation!$D$76))/Inputs!$B$15,0) -> 9.7526444
B12: Current share price | C12: =Inputs!B14 -> 24.5
B13: Base-case value per share | C13: =Valuation!D83 -> 11.453827

Sheet Instructions
B1: READ ME — MODEL v2.2
B3: WHAT CHANGED FROM v1
B4: 1. Beta is now bottom-up. An industry unlevered beta is relevered at the company's own debt-to-equity ratio and country tax rate. The five-year regression against a market index is gone, along with its standard error, the Blume adjustment, the index price series, and the 36-month minimum history requirement.
B5: 2. Normalisation uses the five-year MEDIAN, not the three-year mean. A single distorted year no longer moves the result, and no one has to decide which year was distorted.
B6: 3. The tax rate fades. Stage 1 starts at the company's own median effective rate and converges linearly to the country statutory rate by year 10, because tax shields erode. v1 switched between the two discontinuously.
B7: 4. Mid-year discounting is now applied to the terminal value as well as the explicit years. In v1 it was applied only to the explicit period, which understated value by roughly 3%.
B8: 5. Reinvestment is estimated twice — from cash flows and from the industry sales-to-capital ratio — and the LOWER estimate is used. Conservative by rule.
B9: 6. The cost of debt is the HIGHER of the synthetic spread and the company's actual effective interest rate, capped at 25%.
B10: 7. Five new validation checks: reinvestment divergence, cost-of-debt source, margin and ROIC against industry medians, and a holding-company test on equity-method investments.
B12: THE INPUT RULE
B13: Every input is either (a) read directly from the financial statements, (b) a market-wide parameter, (c) a country parameter set by domicile, or (d) an industry parameter. There are no company-specific judgement values anywhere. If a future change would require one, it does not belong in this model.
B15: WHAT THIS MODEL IS FOR
... B43: The cut-off is fixed in EUR and reviewed annually. A cut-off that floated with EURUSD would reclassify companies, and change their valuations, for no economic reason. D121 warns when a company sits within 20% of it.
